<?xml version="1.0" ?>
<robot name="merlin_arm" xmlns:xacro="http://www.ros.org/wiki/xacro">

<xacro:include filename="$(find merlin)/urdf/materials.xacro" />
<xacro:include filename="$(find merlin)/urdf/merlin_arm.trans" />
<xacro:include filename="$(find merlin)/urdf/merlin_arm.gazebo" />

<link name="world" />

<joint name="world_to_base_link=" type="fixed">
  <parent link="world"/>
  <child link="base_link"/>
</joint>

<link name="base_link">
  <inertial>
    <origin rpy="0 0 0" xyz="1.7695220873355108e-16 0.0 0.14867734601583202"/>
    <mass value="1239.4672431142124"/>
    <inertia ixx="107.195138" ixy="0.0" ixz="0.0" iyy="107.195138" iyz="0.0" izz="141.493257"/>
  </inertial>
  <visual>
    <origin rpy="0 0 0" xyz="0 0 0"/>
    <geometry>
      <mesh filename="package://merlin/meshes/base_link.stl" scale="0.001 0.001 0.001"/>
    </geometry>
    <material name="silver"/>
  </visual>
  <collision>
    <origin rpy="0 0 0" xyz="0 0 0"/>
    <geometry>
      <mesh filename="package://merlin/meshes/base_link.stl" scale="0.001 0.001 0.001"/>
    </geometry>
  </collision>
</link>

<link name="Waist_1">
  <inertial>
    <origin rpy="0 0 0" xyz="0.042236804326939215 -3.6208159165569077e-10 0.3347694485082122"/>
    <mass value="891.2154501387348"/>
    <inertia ixx="37.366081" ixy="-0.0" ixz="6.613944" iyy="52.170529" iyz="-0.0" izz="30.694331"/>
  </inertial>
  <visual>
    <origin rpy="0 0 0" xyz="-0.0 -0.0 -0.762"/>
    <geometry>
      <mesh filename="package://merlin/meshes/Waist_1.stl" scale="0.001 0.001 0.001"/>
    </geometry>
    <material name="red"/>
  </visual>
  <collision>
    <origin rpy="0 0 0" xyz="-0.0 -0.0 -0.762"/>
    <geometry>
      <mesh filename="package://merlin/meshes/Waist_1.stl" scale="0.001 0.001 0.001"/>
    </geometry>
  </collision>
</link>

<link name="Shoulder_Counter_Weight_1">
  <inertial>
    <origin rpy="0 0 0" xyz="1.638658695997039e-06 -0.13471745842372923 0.2124576649582044"/>
    <mass value="163.9417401163658"/>
    <inertia ixx="3.492257" ixy="1e-06" ixz="1.4e-05" iyy="4.256773" iyz="0.177081" izz="1.775182"/>
  </inertial>
  <visual>
    <origin rpy="0 0 0" xyz="0.01126 0.17463 -1.19037"/>
    <geometry>
      <mesh filename="package://merlin/meshes/Shoulder_Counter_Weight_1.stl" scale="0.001 0.001 0.001"/>
    </geometry>
    <material name="red"/>
  </visual>
  <collision>
    <origin rpy="0 0 0" xyz="0.01126 0.17463 -1.19037"/>
    <geometry>
      <mesh filename="package://merlin/meshes/Shoulder_Counter_Weight_1.stl" scale="0.001 0.001 0.001"/>
    </geometry>
  </collision>
</link>

<link name="Shoulder_1">
  <inertial>
    <origin rpy="0 0 0" xyz="4.668484247533772e-07 -0.08204199028652731 -0.21590006858905042"/>
    <mass value="111.15438252619242"/>
    <inertia ixx="3.463174" ixy="0.0" ixz="-0.0" iyy="3.544419" iyz="-0.0" izz="0.458811"/>
  </inertial>
  <visual>
    <origin rpy="0 0 0" xyz="0.01126 0.403332 -1.19037"/>
    <geometry>
      <mesh filename="package://merlin/meshes/Shoulder_1.stl" scale="0.001 0.001 0.001"/>
    </geometry>
    <material name="red"/>
  </visual>
  <collision>
    <origin rpy="0 0 0" xyz="0.01126 0.403332 -1.19037"/>
    <geometry>
      <mesh filename="package://merlin/meshes/Shoulder_1.stl" scale="0.001 0.001 0.001"/>
    </geometry>
  </collision>
</link>

<link name="Elbow_1">
  <inertial>
    <origin rpy="0 0 0" xyz="0.027842767336128563 0.07620048491817272 -8.583596211586553e-08"/>
    <mass value="125.42249263338182"/>
    <inertia ixx="0.541608" ixy="0.0" ixz="0.0" iyy="4.305167" iyz="0.0" izz="4.249064"/>
  </inertial>
  <visual>
    <origin rpy="0 0 0" xyz="0.01126 0.403332 -0.75857"/>
    <geometry>
      <mesh filename="package://merlin/meshes/Elbow_1.stl" scale="0.001 0.001 0.001"/>
    </geometry>
    <material name="red"/>
  </visual>
  <collision>
    <origin rpy="0 0 0" xyz="0.01126 0.403332 -0.75857"/>
    <geometry>
      <mesh filename="package://merlin/meshes/Elbow_1.stl" scale="0.001 0.001 0.001"/>
    </geometry>
  </collision>
</link>

<link name="Head_1">
  <inertial>
    <origin rpy="0 0 0" xyz="-0.08889953829449349 4.849181726718221e-07 -8.583596211586553e-08"/>
    <mass value="17.68067074501873"/>
    <inertia ixx="0.035646" ixy="0.0" ixz="-0.0" iyy="0.064401" iyz="0.0" izz="0.064401"/>
  </inertial>
  <visual>
    <origin rpy="0 0 0" xyz="0.30336 0.327132 -0.75857"/>
    <geometry>
      <mesh filename="package://merlin/meshes/Head_1.stl" scale="0.001 0.001 0.001"/>
    </geometry>
    <material name="black"/>
  </visual>
  <collision>
    <origin rpy="0 0 0" xyz="0.30336 0.327132 -0.75857"/>
    <geometry>
      <mesh filename="package://merlin/meshes/Head_1.stl" scale="0.001 0.001 0.001"/>
    </geometry>
  </collision>
</link>

<joint name="waist_joint" type="revolute">
  <origin rpy="0 0 0" xyz="0.0 0.0 0.762"/>
  <parent link="base_link"/>
  <child link="Waist_1"/>
  <axis xyz="0.0 0.0 1.0"/>
  <limit effort="100" lower="0.0" upper="5.061455" velocity="100"/>
</joint>

<joint name="shoulder_joint" type="continuous">
  <origin rpy="0 0 0" xyz="-0.01126 -0.17463 0.42837"/>
  <parent link="Waist_1"/>
  <child link="Shoulder_Counter_Weight_1"/>
  <axis xyz="0.0 1.0 0.0"/>
</joint>

<joint name="elbow_to_shoulder" type="fixed">
  <origin rpy="0 0 0" xyz="0.0 -0.228702 0.0"/>
  <parent link="Shoulder_Counter_Weight_1"/>
  <child link="Shoulder_1"/>
</joint>

<joint name="elbow_joint" type="continuous">
  <origin rpy="0 0 0" xyz="0.0 0.0 -0.4318"/>
  <parent link="Shoulder_1"/>
  <child link="Elbow_1"/>
  <axis xyz="0.0 -1.0 0.0"/>
</joint>

<joint name="head_to_elbow" type="fixed">
  <origin rpy="0 0 0" xyz="-0.2921 0.0762 0.0"/>
  <parent link="Elbow_1"/>
  <child link="Head_1"/>
</joint>

</robot>
