<?xml version="1.0" ?>
<robot name="merlin" xmlns:xacro="http://www.ros.org/wiki/xacro">

<xacro:include filename="$(find merlin_description)/urdf/materials.xacro" />
<xacro:include filename="$(find merlin_description)/urdf/merlin.trans" />
<xacro:include filename="$(find merlin_description)/urdf/merlin.gazebo" />
<link name="base_link">
  <inertial>
    <origin rpy="0 0 0" xyz="0.0069422690555417796 1.1328659698873208e-16 0.15830248883091955"/>
    <mass value="1290.6879375075011"/>
    <inertia ixx="110.85266" ixy="0.0" ixz="-1.995437" iyy="112.361273" iyz="0.0" izz="143.593266"/>
  </inertial>
  <visual>
    <origin rpy="0 0 0" xyz="0 0 0"/>
    <geometry>
      <mesh filename="package://merlin_description/meshes/base_link.stl" scale="0.001 0.001 0.001"/>
    </geometry>
    <material name="silver"/>
  </visual>
  <collision>
    <origin rpy="0 0 0" xyz="0 0 0"/>
    <geometry>
      <mesh filename="package://merlin_description/meshes/base_link.stl" scale="0.001 0.001 0.001"/>
    </geometry>
  </collision>
</link>

<link name="Waist_1">
  <inertial>
    <origin rpy="0 0 0" xyz="0.049382820138855435 -1.339727353549568e-09 0.2971243460783741"/>
    <mass value="812.9704335382083"/>
    <inertia ixx="28.634617" ixy="-1e-06" ixz="4.185208" iyy="41.522955" iyz="-0.0" izz="28.378178"/>
  </inertial>
  <visual>
    <origin rpy="0 0 0" xyz="-0.0 -0.0 -0.762"/>
    <geometry>
      <mesh filename="package://merlin_description/meshes/Waist_1.stl" scale="0.001 0.001 0.001"/>
    </geometry>
    <material name="red-orange"/>
  </visual>
  <collision>
    <origin rpy="0 0 0" xyz="-0.0 -0.0 -0.762"/>
    <geometry>
      <mesh filename="package://merlin_description/meshes/Waist_1.stl" scale="0.001 0.001 0.001"/>
    </geometry>
  </collision>
</link>

<link name="Shoulder_1">
  <inertial>
    <origin rpy="0 0 0" xyz="0.0 -0.19144610574590126 0.008004317446370424"/>
    <mass value="261.9268819351425"/>
    <inertia ixx="18.724068" ixy="-0.0" ixz="0.0" iyy="17.838364" iyz="-4.08305" izz="3.735585"/>
  </inertial>
  <visual>
    <origin rpy="0 0 0" xyz="0.0 0.1778 -1.119907"/>
    <geometry>
      <mesh filename="package://merlin_description/meshes/Shoulder_1.stl" scale="0.001 0.001 0.001"/>
    </geometry>
    <material name="red-orange"/>
  </visual>
  <collision>
    <origin rpy="0 0 0" xyz="0.0 0.1778 -1.119907"/>
    <geometry>
      <mesh filename="package://merlin_description/meshes/Shoulder_1.stl" scale="0.001 0.001 0.001"/>
    </geometry>
  </collision>
</link>

<link name="Lower_Head_1">
  <inertial>
    <origin rpy="0 0 0" xyz="-0.0361575070816591 3.3861802251067274e-15 1.7643049632365404e-07"/>
    <mass value="2.2131276746402757"/>
    <inertia ixx="0.0067" ixy="-0.0" ixz="0.0" iyy="0.007083" iyz="0.0" izz="0.004151"/>
  </inertial>
  <visual>
    <origin rpy="0 0 0" xyz="0.355626 0.3048 -0.721755"/>
    <geometry>
      <mesh filename="package://merlin_description/meshes/Lower_Head_1.stl" scale="0.001 0.001 0.001"/>
    </geometry>
    <material name="silver"/>
  </visual>
  <collision>
    <origin rpy="0 0 0" xyz="0.355626 0.3048 -0.721755"/>
    <geometry>
      <mesh filename="package://merlin_description/meshes/Lower_Head_1.stl" scale="0.001 0.001 0.001"/>
    </geometry>
  </collision>
</link>

<link name="Upper_Head_1">
  <inertial>
    <origin rpy="0 0 0" xyz="-0.055606550532396326 3.3306690738754696e-16 0.04584517643050223"/>
    <mass value="3.012798664762447"/>
    <inertia ixx="0.004849" ixy="0.0" ixz="-0.0" iyy="0.006079" iyz="-0.0" izz="0.004733"/>
  </inertial>
  <visual>
    <origin rpy="0 0 0" xyz="0.437922 0.3048 -0.67591"/>
    <geometry>
      <mesh filename="package://merlin_description/meshes/Upper_Head_1.stl" scale="0.001 0.001 0.001"/>
    </geometry>
    <material name="silver"/>
  </visual>
  <collision>
    <origin rpy="0 0 0" xyz="0.437922 0.3048 -0.67591"/>
    <geometry>
      <mesh filename="package://merlin_description/meshes/Upper_Head_1.stl" scale="0.001 0.001 0.001"/>
    </geometry>
  </collision>
</link>

<link name="Face_Plate_1">
  <inertial>
    <origin rpy="0 0 0" xyz="-0.00393824468089865 0.0 1.764304806695094e-07"/>
    <mass value="0.47960575442808734"/>
    <inertia ixx="0.000647" ixy="-0.0" ixz="0.0" iyy="0.000326" iyz="0.0" izz="0.000326"/>
  </inertial>
  <visual>
    <origin rpy="0 0 0" xyz="0.526822 0.3048 -0.721755"/>
    <geometry>
      <mesh filename="package://merlin_description/meshes/Face_Plate_1.stl" scale="0.001 0.001 0.001"/>
    </geometry>
    <material name="black"/>
  </visual>
  <collision>
    <origin rpy="0 0 0" xyz="0.526822 0.3048 -0.721755"/>
    <geometry>
      <mesh filename="package://merlin_description/meshes/Face_Plate_1.stl" scale="0.001 0.001 0.001"/>
    </geometry>
  </collision>
</link>

<link name="Elbow_1">
  <inertial>
    <origin rpy="0 0 0" xyz="-0.024097643370389953 0.07620000000000005 0.043300176430502546"/>
    <mass value="131.1743823904856"/>
    <inertia ixx="0.57509" ixy="-0.0" ixz="0.0" iyy="4.777681" iyz="0.0" izz="4.709359"/>
  </inertial>
  <visual>
    <origin rpy="0 0 0" xyz="-0.0 0.381 -0.678455"/>
    <geometry>
      <mesh filename="package://merlin_description/meshes/Elbow_1.stl" scale="0.001 0.001 0.001"/>
    </geometry>
    <material name="red-orange"/>
  </visual>
  <collision>
    <origin rpy="0 0 0" xyz="-0.0 0.381 -0.678455"/>
    <geometry>
      <mesh filename="package://merlin_description/meshes/Elbow_1.stl" scale="0.001 0.001 0.001"/>
    </geometry>
  </collision>
</link>

<joint name="waist" type="revolute">
  <origin rpy="0 0 0" xyz="0.0 0.0 0.762"/>
  <parent link="base_link"/>
  <child link="Waist_1"/>
  <axis xyz="0.0 0.0 1.0"/>
  <limit effort="100" lower="0.0" upper="5.061455" velocity="100"/>
</joint>

<joint name="shoulder" type="continuous">
  <origin rpy="0 0 0" xyz="-0.0 -0.1778 0.357907"/>
  <parent link="Waist_1"/>
  <child link="Shoulder_1"/>
  <axis xyz="0.0 -1.0 0.0"/>
</joint>

<joint name="wrist_rotation" type="continuous">
  <origin rpy="0 0 0" xyz="-0.355626 0.0762 0.0433"/>
  <parent link="Elbow_1"/>
  <child link="Lower_Head_1"/>
  <axis xyz="-1.0 0.0 -0.0"/>
</joint>

<joint name="wrist_flex" type="revolute">
  <origin rpy="0 0 0" xyz="-0.082296 0.0 -0.045845"/>
  <parent link="Lower_Head_1"/>
  <child link="Upper_Head_1"/>
  <axis xyz="-0.0 0.0 1.0"/>
  <limit effort="100" lower="-1.570796" upper="1.570796" velocity="100"/>
</joint>

<joint name="hand_roll" type="continuous">
  <origin rpy="0 0 0" xyz="-0.0889 0.0 0.045845"/>
  <parent link="Upper_Head_1"/>
  <child link="Face_Plate_1"/>
  <axis xyz="-1.0 0.0 0.0"/>
</joint>

<joint name="elbow" type="continuous">
  <origin rpy="0 0 0" xyz="0.0 -0.2032 -0.441452"/>
  <parent link="Shoulder_1"/>
  <child link="Elbow_1"/>
  <axis xyz="0.0 -1.0 0.0"/>
</joint>

</robot>
