<?xml version="1.0" ?>
<robot name="merlin" xmlns:xacro="http://www.ros.org/wiki/xacro">

<xacro:include filename="$(find merlin_description)/urdf/materials.xacro" />
<xacro:include filename="$(find merlin_description)/urdf/merlin.trans" />
<xacro:include filename="$(find merlin_description)/urdf/merlin.gazebo" />
<link name="base_link">
  <inertial>
    <origin rpy="0 0 0" xyz="0.0069422690555417796 1.1328659698873208e-16 0.15830248883091955"/>
    <mass value="1290.6879375075011"/>
    <inertia ixx="110.85266" ixy="0.0" ixz="-1.995437" iyy="112.361273" iyz="0.0" izz="143.593266"/>
  </inertial>
  <visual>
    <origin rpy="0 0 0" xyz="0 0 0"/>
    <geometry>
      <mesh filename="package://merlin_description/meshes/base_link.stl" scale="0.001 0.001 0.001"/>
    </geometry>
    <material name="silver"/>
  </visual>
  <collision>
    <origin rpy="0 0 0" xyz="0 0 0"/>
    <geometry>
      <mesh filename="package://merlin_description/meshes/base_link.stl" scale="0.001 0.001 0.001"/>
    </geometry>
  </collision>
</link>

<link name="Waist_1">
  <inertial>
    <origin rpy="0 0 0" xyz="0.042236804326939215 -3.6208159165569077e-10 0.3347694485082122"/>
    <mass value="891.2154501387348"/>
    <inertia ixx="37.366081" ixy="-0.0" ixz="6.613944" iyy="52.170529" iyz="-0.0" izz="30.694331"/>
  </inertial>
  <visual>
    <origin rpy="0 0 0" xyz="-0.0 -0.0 -0.762"/>
    <geometry>
      <mesh filename="package://merlin_description/meshes/Waist_1.stl" scale="0.001 0.001 0.001"/>
    </geometry>
    <material name="red-orange"/>
  </visual>
  <collision>
    <origin rpy="0 0 0" xyz="-0.0 -0.0 -0.762"/>
    <geometry>
      <mesh filename="package://merlin_description/meshes/Waist_1.stl" scale="0.001 0.001 0.001"/>
    </geometry>
  </collision>
</link>

<link name="Shoulder_Counter_Weight_1">
  <inertial>
    <origin rpy="0 0 0" xyz="1.638658695997039e-06 -0.13471745842372923 0.2124576649582044"/>
    <mass value="163.9417401163658"/>
    <inertia ixx="3.492257" ixy="1e-06" ixz="1.4e-05" iyy="4.256773" iyz="0.177081" izz="1.775182"/>
  </inertial>
  <visual>
    <origin rpy="0 0 0" xyz="0.01126 0.17463 -1.19037"/>
    <geometry>
      <mesh filename="package://merlin_description/meshes/Shoulder_Counter_Weight_1.stl" scale="0.001 0.001 0.001"/>
    </geometry>
    <material name="red-orange"/>
  </visual>
  <collision>
    <origin rpy="0 0 0" xyz="0.01126 0.17463 -1.19037"/>
    <geometry>
      <mesh filename="package://merlin_description/meshes/Shoulder_Counter_Weight_1.stl" scale="0.001 0.001 0.001"/>
    </geometry>
  </collision>
</link>

<link name="Shoulder_1">
  <inertial>
    <origin rpy="0 0 0" xyz="4.668484247533772e-07 -0.08204199028652731 -0.21590006858905042"/>
    <mass value="111.15438252619242"/>
    <inertia ixx="3.463174" ixy="0.0" ixz="-0.0" iyy="3.544419" iyz="-0.0" izz="0.458811"/>
  </inertial>
  <visual>
    <origin rpy="0 0 0" xyz="0.01126 0.403332 -1.19037"/>
    <geometry>
      <mesh filename="package://merlin_description/meshes/Shoulder_1.stl" scale="0.001 0.001 0.001"/>
    </geometry>
    <material name="red-orange"/>
  </visual>
  <collision>
    <origin rpy="0 0 0" xyz="0.01126 0.403332 -1.19037"/>
    <geometry>
      <mesh filename="package://merlin_description/meshes/Shoulder_1.stl" scale="0.001 0.001 0.001"/>
    </geometry>
  </collision>
</link>

<link name="Elbow_1">
  <inertial>
    <origin rpy="0 0 0" xyz="0.027842767336128563 0.07620048491817272 -8.583596211586553e-08"/>
    <mass value="125.42249263338182"/>
    <inertia ixx="0.541608" ixy="0.0" ixz="0.0" iyy="4.305167" iyz="0.0" izz="4.249064"/>
  </inertial>
  <visual>
    <origin rpy="0 0 0" xyz="0.01126 0.403332 -0.75857"/>
    <geometry>
      <mesh filename="package://merlin_description/meshes/Elbow_1.stl" scale="0.001 0.001 0.001"/>
    </geometry>
    <material name="red-orange"/>
  </visual>
  <collision>
    <origin rpy="0 0 0" xyz="0.01126 0.403332 -0.75857"/>
    <geometry>
      <mesh filename="package://merlin_description/meshes/Elbow_1.stl" scale="0.001 0.001 0.001"/>
    </geometry>
  </collision>
</link>

<link name="Lower_Head_1">
  <inertial>
    <origin rpy="0 0 0" xyz="-0.037149268691422266 4.849181761135135e-07 -8.58359701094713e-08"/>
    <mass value="2.3452928353268896"/>
    <inertia ixx="0.007908" ixy="-0.0" ixz="0.0" iyy="0.008302" iyz="0.0" izz="0.004782"/>
  </inertial>
  <visual>
    <origin rpy="0 0 0" xyz="0.30336 0.327132 -0.75857"/>
    <geometry>
      <mesh filename="package://merlin_description/meshes/Lower_Head_1.stl" scale="0.001 0.001 0.001"/>
    </geometry>
    <material name="silver"/>
  </visual>
  <collision>
    <origin rpy="0 0 0" xyz="0.30336 0.327132 -0.75857"/>
    <geometry>
      <mesh filename="package://merlin_description/meshes/Lower_Head_1.stl" scale="0.001 0.001 0.001"/>
    </geometry>
  </collision>
</link>

<link name="Upper_Head_1">
  <inertial>
    <origin rpy="0 0 0" xyz="-0.05114769265014063 4.849181650667944e-07 0.048955914164058534"/>
    <mass value="3.5935679649522583"/>
    <inertia ixx="0.006277" ixy="0.0" ixz="-0.0" iyy="0.006232" iyz="-0.0" izz="0.00493"/>
  </inertial>
  <visual>
    <origin rpy="0 0 0" xyz="0.389755 0.327132 -0.709614"/>
    <geometry>
      <mesh filename="package://merlin_description/meshes/Upper_Head_1.stl" scale="0.001 0.001 0.001"/>
    </geometry>
    <material name="silver"/>
  </visual>
  <collision>
    <origin rpy="0 0 0" xyz="0.389755 0.327132 -0.709614"/>
    <geometry>
      <mesh filename="package://merlin_description/meshes/Upper_Head_1.stl" scale="0.001 0.001 0.001"/>
    </geometry>
  </collision>
</link>

<link name="Face_Plate_1">
  <inertial>
    <origin rpy="0 0 0" xyz="-0.00393831587789073 4.849181727273333e-07 -8.58359836541922e-08"/>
    <mass value="0.4796057544280874"/>
    <inertia ixx="0.000647" ixy="-0.0" ixz="0.0" iyy="0.000326" iyz="0.0" izz="0.000326"/>
  </inertial>
  <visual>
    <origin rpy="0 0 0" xyz="0.470326 0.327132 -0.75857"/>
    <geometry>
      <mesh filename="package://merlin_description/meshes/Face_Plate_1.stl" scale="0.001 0.001 0.001"/>
    </geometry>
    <material name="black"/>
  </visual>
  <collision>
    <origin rpy="0 0 0" xyz="0.470326 0.327132 -0.75857"/>
    <geometry>
      <mesh filename="package://merlin_description/meshes/Face_Plate_1.stl" scale="0.001 0.001 0.001"/>
    </geometry>
  </collision>
</link>

<joint name="waist" type="revolute">
  <origin rpy="0 0 0" xyz="0.0 0.0 0.762"/>
  <parent link="base_link"/>
  <child link="Waist_1"/>
  <axis xyz="0.0 0.0 1.0"/>
  <limit effort="100" lower="0.0" upper="5.061455" velocity="100"/>
</joint>

<joint name="shoulder" type="continuous">
  <origin rpy="0 0 0" xyz="-0.01126 -0.17463 0.42837"/>
  <parent link="Waist_1"/>
  <child link="Shoulder_Counter_Weight_1"/>
  <axis xyz="0.0 1.0 0.0"/>
</joint>

<joint name="elbow_to_shoulder" type="fixed">
  <origin rpy="0 0 0" xyz="0.0 -0.228702 0.0"/>
  <parent link="Shoulder_Counter_Weight_1"/>
  <child link="Shoulder_1"/>
</joint>

<joint name="elbow" type="continuous">
  <origin rpy="0 0 0" xyz="0.0 0.0 -0.4318"/>
  <parent link="Shoulder_1"/>
  <child link="Elbow_1"/>
  <axis xyz="0.0 -1.0 0.0"/>
</joint>

<joint name="wrist_rotation" type="continuous">
  <origin rpy="0 0 0" xyz="-0.2921 0.0762 0.0"/>
  <parent link="Elbow_1"/>
  <child link="Lower_Head_1"/>
  <axis xyz="-1.0 0.0 0.0"/>
</joint>

<joint name="wrist_flex" type="revolute">
  <origin rpy="0 0 0" xyz="-0.086395 0.0 -0.048956"/>
  <parent link="Lower_Head_1"/>
  <child link="Upper_Head_1"/>
  <axis xyz="0.0 0.0 1.0"/>
  <limit effort="100" lower="-1.570796" upper="1.570796" velocity="100"/>
</joint>

<joint name="hand_roll" type="continuous">
  <origin rpy="0 0 0" xyz="-0.080571 0.0 0.048956"/>
  <parent link="Upper_Head_1"/>
  <child link="Face_Plate_1"/>
  <axis xyz="-1.0 0.0 0.0"/>
</joint>

</robot>
